[2024-05-28T18:53:30.498+0000] {taskinstance.py:1956} INFO - Dependencies all met for dep_context=non-requeueable deps ti=<TaskInstance: retries_dag.my_failed_task manual__2024-05-28T18:51:43.130325+00:00 [queued]>
[2024-05-28T18:53:30.516+0000] {taskinstance.py:1956} INFO - Dependencies all met for dep_context=requeueable deps ti=<TaskInstance: retries_dag.my_failed_task manual__2024-05-28T18:51:43.130325+00:00 [queued]>
[2024-05-28T18:53:30.517+0000] {taskinstance.py:2170} INFO - Starting attempt 4 of 6
[2024-05-28T18:53:30.553+0000] {taskinstance.py:2191} INFO - Executing <Task(PythonOperator): my_failed_task> on 2024-05-28 18:51:43.130325+00:00
[2024-05-28T18:53:30.566+0000] {standard_task_runner.py:60} INFO - Started process 4281 to run task
[2024-05-28T18:53:30.570+0000] {standard_task_runner.py:87} INFO - Running: ['***', 'tasks', 'run', 'retries_dag', 'my_failed_task', 'manual__2024-05-28T18:51:43.130325+00:00', '--job-id', '239', '--raw', '--subdir', 'DAGS_FOLDER/retries_dag.py', '--cfg-path', '/tmp/tmp394g4_zf']
[2024-05-28T18:53:30.579+0000] {standard_task_runner.py:88} INFO - Job 239: Subtask my_failed_task
[2024-05-28T18:53:30.605+0000] {warnings.py:109} WARNING - /home/***/.local/lib/python3.8/site-packages/***/settings.py:194: DeprecationWarning: The sql_alchemy_conn option in [core] has been moved to the sql_alchemy_conn option in [database] - the old setting has been used, but please update your config.
  SQL_ALCHEMY_CONN = conf.get("database", "SQL_ALCHEMY_CONN")

[2024-05-28T18:53:30.694+0000] {task_command.py:423} INFO - Running <TaskInstance: retries_dag.my_failed_task manual__2024-05-28T18:51:43.130325+00:00 [running]> on host ac6c883b25f7
[2024-05-28T18:53:30.872+0000] {taskinstance.py:2480} INFO - Exporting env vars: AIRFLOW_CTX_DAG_OWNER='***' AIRFLOW_CTX_DAG_ID='retries_dag' AIRFLOW_CTX_TASK_ID='my_failed_task' AIRFLOW_CTX_EXECUTION_DATE='2024-05-28T18:51:43.130325+00:00' AIRFLOW_CTX_TRY_NUMBER='4' AIRFLOW_CTX_DAG_RUN_ID='manual__2024-05-28T18:51:43.130325+00:00'
[2024-05-28T18:53:30.874+0000] {taskinstance.py:2698} ERROR - Task failed with exception
Traceback (most recent call last):
  File "/home/airflow/.local/lib/python3.8/site-packages/airflow/models/taskinstance.py", line 433, in _execute_task
    result = execute_callable(context=context, **execute_callable_kwargs)
  File "/home/airflow/.local/lib/python3.8/site-packages/airflow/operators/python.py", line 199, in execute
    return_value = self.execute_callable()
  File "/home/airflow/.local/lib/python3.8/site-packages/airflow/operators/python.py", line 216, in execute_callable
    return self.python_callable(*self.op_args, **self.op_kwargs)
  File "/opt/airflow/dags/retries_dag.py", line 7, in failed_task
    raise Exception('This task did not work!')
Exception: This task did not work!
[2024-05-28T18:53:30.897+0000] {taskinstance.py:1138} INFO - Marking task as UP_FOR_RETRY. dag_id=retries_dag, task_id=my_failed_task, execution_date=20240528T185143, start_date=20240528T185330, end_date=20240528T185330
[2024-05-28T18:53:30.920+0000] {standard_task_runner.py:107} ERROR - Failed to execute job 239 for task my_failed_task (This task did not work!; 4281)
[2024-05-28T18:53:30.952+0000] {local_task_job_runner.py:234} INFO - Task exited with return code 1
[2024-05-28T18:53:30.992+0000] {taskinstance.py:3280} INFO - 0 downstream tasks scheduled from follow-on schedule check
