[2024-05-28T18:32:39.781+0000] {taskinstance.py:1956} INFO - Dependencies all met for dep_context=non-requeueable deps ti=<TaskInstance: fork1_dag.task2 manual__2024-05-28T18:32:29.871792+00:00 [queued]>
[2024-05-28T18:32:39.863+0000] {taskinstance.py:1956} INFO - Dependencies all met for dep_context=requeueable deps ti=<TaskInstance: fork1_dag.task2 manual__2024-05-28T18:32:29.871792+00:00 [queued]>
[2024-05-28T18:32:39.864+0000] {taskinstance.py:2170} INFO - Starting attempt 1 of 1
[2024-05-28T18:32:39.970+0000] {taskinstance.py:2191} INFO - Executing <Task(PythonOperator): task2> on 2024-05-28 18:32:29.871792+00:00
[2024-05-28T18:32:40.013+0000] {standard_task_runner.py:60} INFO - Started process 3462 to run task
[2024-05-28T18:32:40.038+0000] {standard_task_runner.py:87} INFO - Running: ['***', 'tasks', 'run', 'fork1_dag', 'task2', 'manual__2024-05-28T18:32:29.871792+00:00', '--job-id', '182', '--raw', '--subdir', 'DAGS_FOLDER/fork_1.py', '--cfg-path', '/tmp/tmpe4vzfnbc']
[2024-05-28T18:32:40.053+0000] {standard_task_runner.py:88} INFO - Job 182: Subtask task2
[2024-05-28T18:32:40.125+0000] {warnings.py:109} WARNING - /home/***/.local/lib/python3.8/site-packages/***/settings.py:194: DeprecationWarning: The sql_alchemy_conn option in [core] has been moved to the sql_alchemy_conn option in [database] - the old setting has been used, but please update your config.
  SQL_ALCHEMY_CONN = conf.get("database", "SQL_ALCHEMY_CONN")

[2024-05-28T18:32:40.300+0000] {task_command.py:423} INFO - Running <TaskInstance: fork1_dag.task2 manual__2024-05-28T18:32:29.871792+00:00 [running]> on host ac6c883b25f7
[2024-05-28T18:32:40.613+0000] {taskinstance.py:2480} INFO - Exporting env vars: AIRFLOW_CTX_DAG_OWNER='***' AIRFLOW_CTX_DAG_ID='fork1_dag' AIRFLOW_CTX_TASK_ID='task2' AIRFLOW_CTX_EXECUTION_DATE='2024-05-28T18:32:29.871792+00:00' AIRFLOW_CTX_TRY_NUMBER='1' AIRFLOW_CTX_DAG_RUN_ID='manual__2024-05-28T18:32:29.871792+00:00'
[2024-05-28T18:32:40.615+0000] {taskinstance.py:2698} ERROR - Task failed with exception
Traceback (most recent call last):
  File "/home/airflow/.local/lib/python3.8/site-packages/airflow/models/taskinstance.py", line 433, in _execute_task
    result = execute_callable(context=context, **execute_callable_kwargs)
  File "/home/airflow/.local/lib/python3.8/site-packages/airflow/operators/python.py", line 199, in execute
    return_value = self.execute_callable()
  File "/home/airflow/.local/lib/python3.8/site-packages/airflow/operators/python.py", line 216, in execute_callable
    return self.python_callable(*self.op_args, **self.op_kwargs)
  File "/opt/airflow/dags/fork_1.py", line 11, in failed_task
    raise Exception('This task did not work!')
Exception: This task did not work!
[2024-05-28T18:32:40.654+0000] {taskinstance.py:1138} INFO - Marking task as FAILED. dag_id=fork1_dag, task_id=task2, execution_date=20240528T183229, start_date=20240528T183239, end_date=20240528T183240
[2024-05-28T18:32:40.702+0000] {standard_task_runner.py:107} ERROR - Failed to execute job 182 for task task2 (This task did not work!; 3462)
[2024-05-28T18:32:40.796+0000] {local_task_job_runner.py:234} INFO - Task exited with return code 1
[2024-05-28T18:32:40.865+0000] {taskinstance.py:3280} INFO - 0 downstream tasks scheduled from follow-on schedule check
