[2024-05-28T19:12:02.401+0000] {taskinstance.py:1956} INFO - Dependencies all met for dep_context=non-requeueable deps ti=<TaskInstance: fork3_dag.task3 scheduled__2024-05-28T19:11:20+00:00 [queued]>
[2024-05-28T19:12:02.711+0000] {taskinstance.py:1956} INFO - Dependencies all met for dep_context=requeueable deps ti=<TaskInstance: fork3_dag.task3 scheduled__2024-05-28T19:11:20+00:00 [queued]>
[2024-05-28T19:12:02.712+0000] {taskinstance.py:2170} INFO - Starting attempt 1 of 1
[2024-05-28T19:12:02.987+0000] {taskinstance.py:2191} INFO - Executing <Task(PythonOperator): task3> on 2024-05-28 19:11:20+00:00
[2024-05-28T19:12:03.066+0000] {standard_task_runner.py:60} INFO - Started process 4946 to run task
[2024-05-28T19:12:03.107+0000] {standard_task_runner.py:87} INFO - Running: ['***', 'tasks', 'run', 'fork3_dag', 'task3', 'scheduled__2024-05-28T19:11:20+00:00', '--job-id', '260', '--raw', '--subdir', 'DAGS_FOLDER/fork_3.py', '--cfg-path', '/tmp/tmpd_908ruy']
[2024-05-28T19:12:03.127+0000] {standard_task_runner.py:88} INFO - Job 260: Subtask task3
[2024-05-28T19:12:03.215+0000] {warnings.py:109} WARNING - /home/***/.local/lib/python3.8/site-packages/***/settings.py:194: DeprecationWarning: The sql_alchemy_conn option in [core] has been moved to the sql_alchemy_conn option in [database] - the old setting has been used, but please update your config.
  SQL_ALCHEMY_CONN = conf.get("database", "SQL_ALCHEMY_CONN")

[2024-05-28T19:12:03.709+0000] {task_command.py:423} INFO - Running <TaskInstance: fork3_dag.task3 scheduled__2024-05-28T19:11:20+00:00 [running]> on host ac6c883b25f7
[2024-05-28T19:12:04.831+0000] {taskinstance.py:2480} INFO - Exporting env vars: AIRFLOW_CTX_DAG_OWNER='***' AIRFLOW_CTX_DAG_ID='fork3_dag' AIRFLOW_CTX_TASK_ID='task3' AIRFLOW_CTX_EXECUTION_DATE='2024-05-28T19:11:20+00:00' AIRFLOW_CTX_TRY_NUMBER='1' AIRFLOW_CTX_DAG_RUN_ID='scheduled__2024-05-28T19:11:20+00:00'
[2024-05-28T19:12:04.835+0000] {logging_mixin.py:188} INFO - 0.23773265912287767
[2024-05-28T19:12:04.855+0000] {taskinstance.py:2698} ERROR - Task failed with exception
Traceback (most recent call last):
  File "/home/airflow/.local/lib/python3.8/site-packages/airflow/models/taskinstance.py", line 433, in _execute_task
    result = execute_callable(context=context, **execute_callable_kwargs)
  File "/home/airflow/.local/lib/python3.8/site-packages/airflow/operators/python.py", line 199, in execute
    return_value = self.execute_callable()
  File "/home/airflow/.local/lib/python3.8/site-packages/airflow/operators/python.py", line 216, in execute_callable
    return self.python_callable(*self.op_args, **self.op_kwargs)
  File "/opt/airflow/dags/fork_3.py", line 20, in random_fail_task
    raise Exception('This task randomly failed')
Exception: This task randomly failed
[2024-05-28T19:12:04.935+0000] {taskinstance.py:1138} INFO - Marking task as FAILED. dag_id=fork3_dag, task_id=task3, execution_date=20240528T191120, start_date=20240528T191202, end_date=20240528T191204
[2024-05-28T19:12:05.211+0000] {standard_task_runner.py:107} ERROR - Failed to execute job 260 for task task3 (This task randomly failed; 4946)
[2024-05-28T19:12:05.359+0000] {local_task_job_runner.py:234} INFO - Task exited with return code 1
[2024-05-28T19:12:05.651+0000] {taskinstance.py:3280} INFO - 1 downstream tasks scheduled from follow-on schedule check
