[2024-05-28T18:40:55.213+0000] {taskinstance.py:1956} INFO - Dependencies all met for dep_context=non-requeueable deps ti=<TaskInstance: fork2_dag.task1 scheduled__2024-05-28T18:40:10+00:00 [queued]>
[2024-05-28T18:40:55.249+0000] {taskinstance.py:1956} INFO - Dependencies all met for dep_context=requeueable deps ti=<TaskInstance: fork2_dag.task1 scheduled__2024-05-28T18:40:10+00:00 [queued]>
[2024-05-28T18:40:55.250+0000] {taskinstance.py:2170} INFO - Starting attempt 1 of 1
[2024-05-28T18:40:55.335+0000] {taskinstance.py:2191} INFO - Executing <Task(PythonOperator): task1> on 2024-05-28 18:40:10+00:00
[2024-05-28T18:40:55.364+0000] {standard_task_runner.py:60} INFO - Started process 3735 to run task
[2024-05-28T18:40:55.408+0000] {standard_task_runner.py:87} INFO - Running: ['***', 'tasks', 'run', 'fork2_dag', 'task1', 'scheduled__2024-05-28T18:40:10+00:00', '--job-id', '184', '--raw', '--subdir', 'DAGS_FOLDER/fork_2.py', '--cfg-path', '/tmp/tmp1_g12fi6']
[2024-05-28T18:40:55.424+0000] {standard_task_runner.py:88} INFO - Job 184: Subtask task1
[2024-05-28T18:40:55.492+0000] {warnings.py:109} WARNING - /home/***/.local/lib/python3.8/site-packages/***/settings.py:194: DeprecationWarning: The sql_alchemy_conn option in [core] has been moved to the sql_alchemy_conn option in [database] - the old setting has been used, but please update your config.
  SQL_ALCHEMY_CONN = conf.get("database", "SQL_ALCHEMY_CONN")

[2024-05-28T18:40:55.699+0000] {task_command.py:423} INFO - Running <TaskInstance: fork2_dag.task1 scheduled__2024-05-28T18:40:10+00:00 [running]> on host ac6c883b25f7
[2024-05-28T18:40:56.103+0000] {taskinstance.py:2480} INFO - Exporting env vars: AIRFLOW_CTX_DAG_OWNER='***' AIRFLOW_CTX_DAG_ID='fork2_dag' AIRFLOW_CTX_TASK_ID='task1' AIRFLOW_CTX_EXECUTION_DATE='2024-05-28T18:40:10+00:00' AIRFLOW_CTX_TRY_NUMBER='1' AIRFLOW_CTX_DAG_RUN_ID='scheduled__2024-05-28T18:40:10+00:00'
[2024-05-28T18:40:56.118+0000] {logging_mixin.py:188} INFO - 0.4600508368188415
[2024-05-28T18:40:56.118+0000] {taskinstance.py:2698} ERROR - Task failed with exception
Traceback (most recent call last):
  File "/home/airflow/.local/lib/python3.8/site-packages/airflow/models/taskinstance.py", line 433, in _execute_task
    result = execute_callable(context=context, **execute_callable_kwargs)
  File "/home/airflow/.local/lib/python3.8/site-packages/airflow/operators/python.py", line 199, in execute
    return_value = self.execute_callable()
  File "/home/airflow/.local/lib/python3.8/site-packages/airflow/operators/python.py", line 216, in execute_callable
    return self.python_callable(*self.op_args, **self.op_kwargs)
  File "/opt/airflow/dags/fork_2.py", line 20, in random_fail_task
    raise Exception('This task randomly failed')
Exception: This task randomly failed
[2024-05-28T18:40:56.131+0000] {taskinstance.py:1138} INFO - Marking task as FAILED. dag_id=fork2_dag, task_id=task1, execution_date=20240528T184010, start_date=20240528T184055, end_date=20240528T184056
[2024-05-28T18:40:56.169+0000] {standard_task_runner.py:107} ERROR - Failed to execute job 184 for task task1 (This task randomly failed; 3735)
[2024-05-28T18:40:56.235+0000] {local_task_job_runner.py:234} INFO - Task exited with return code 1
[2024-05-28T18:40:56.412+0000] {taskinstance.py:3280} INFO - 0 downstream tasks scheduled from follow-on schedule check
