[2024-05-26T14:02:01.492+0000] {taskinstance.py:1956} INFO - Dependencies all met for dep_context=non-requeueable deps ti=<TaskInstance: my_very_first_dag.my_very_first_task manual__2024-05-26T14:01:57.905879+00:00 [queued]>
[2024-05-26T14:02:01.509+0000] {taskinstance.py:1956} INFO - Dependencies all met for dep_context=requeueable deps ti=<TaskInstance: my_very_first_dag.my_very_first_task manual__2024-05-26T14:01:57.905879+00:00 [queued]>
[2024-05-26T14:02:01.509+0000] {taskinstance.py:2170} INFO - Starting attempt 1 of 1
[2024-05-26T14:02:01.539+0000] {taskinstance.py:2191} INFO - Executing <Task(PythonOperator): my_very_first_task> on 2024-05-26 14:01:57.905879+00:00
[2024-05-26T14:02:01.551+0000] {standard_task_runner.py:60} INFO - Started process 5847 to run task
[2024-05-26T14:02:01.555+0000] {standard_task_runner.py:87} INFO - Running: ['***', 'tasks', 'run', 'my_very_first_dag', 'my_very_first_task', 'manual__2024-05-26T14:01:57.905879+00:00', '--job-id', '12', '--raw', '--subdir', 'DAGS_FOLDER/my_first_dag.py', '--cfg-path', '/tmp/tmp6dzyp9w_']
[2024-05-26T14:02:01.560+0000] {standard_task_runner.py:88} INFO - Job 12: Subtask my_very_first_task
[2024-05-26T14:02:01.592+0000] {warnings.py:109} WARNING - /home/***/.local/lib/python3.8/site-packages/***/settings.py:194: DeprecationWarning: The sql_alchemy_conn option in [core] has been moved to the sql_alchemy_conn option in [database] - the old setting has been used, but please update your config.
  SQL_ALCHEMY_CONN = conf.get("database", "SQL_ALCHEMY_CONN")

[2024-05-26T14:02:01.670+0000] {task_command.py:423} INFO - Running <TaskInstance: my_very_first_dag.my_very_first_task manual__2024-05-26T14:01:57.905879+00:00 [running]> on host ac6c883b25f7
[2024-05-26T14:02:01.859+0000] {taskinstance.py:2480} INFO - Exporting env vars: AIRFLOW_CTX_DAG_OWNER='***' AIRFLOW_CTX_DAG_ID='my_very_first_dag' AIRFLOW_CTX_TASK_ID='my_very_first_task' AIRFLOW_CTX_EXECUTION_DATE='2024-05-26T14:01:57.905879+00:00' AIRFLOW_CTX_TRY_NUMBER='1' AIRFLOW_CTX_DAG_RUN_ID='manual__2024-05-26T14:01:57.905879+00:00'
[2024-05-26T14:02:01.862+0000] {taskinstance.py:2698} ERROR - Task failed with exception
Traceback (most recent call last):
  File "/home/airflow/.local/lib/python3.8/site-packages/airflow/models/taskinstance.py", line 433, in _execute_task
    result = execute_callable(context=context, **execute_callable_kwargs)
  File "/home/airflow/.local/lib/python3.8/site-packages/airflow/operators/python.py", line 199, in execute
    return_value = self.execute_callable()
  File "/home/airflow/.local/lib/python3.8/site-packages/airflow/operators/python.py", line 216, in execute_callable
    return self.python_callable(*self.op_args, **self.op_kwargs)
  File "/opt/airflow/dags/my_first_dag.py", line 19, in print_date_and_hello
    time.sleep(30)
NameError: name 'time' is not defined
[2024-05-26T14:02:01.877+0000] {taskinstance.py:1138} INFO - Marking task as FAILED. dag_id=my_very_first_dag, task_id=my_very_first_task, execution_date=20240526T140157, start_date=20240526T140201, end_date=20240526T140201
[2024-05-26T14:02:01.900+0000] {standard_task_runner.py:107} ERROR - Failed to execute job 12 for task my_very_first_task (name 'time' is not defined; 5847)
[2024-05-26T14:02:01.939+0000] {local_task_job_runner.py:234} INFO - Task exited with return code 1
[2024-05-26T14:02:01.980+0000] {taskinstance.py:3280} INFO - 0 downstream tasks scheduled from follow-on schedule check
