[2024-05-28T18:40:55.970+0000] {taskinstance.py:1956} INFO - Dependencies all met for dep_context=non-requeueable deps ti=<TaskInstance: fork2_dag.task1 scheduled__2024-05-28T18:40:40+00:00 [queued]>
[2024-05-28T18:40:56.039+0000] {taskinstance.py:1956} INFO - Dependencies all met for dep_context=requeueable deps ti=<TaskInstance: fork2_dag.task1 scheduled__2024-05-28T18:40:40+00:00 [queued]>
[2024-05-28T18:40:56.040+0000] {taskinstance.py:2170} INFO - Starting attempt 1 of 1
[2024-05-28T18:40:56.109+0000] {taskinstance.py:2191} INFO - Executing <Task(PythonOperator): task1> on 2024-05-28 18:40:40+00:00
[2024-05-28T18:40:56.138+0000] {standard_task_runner.py:60} INFO - Started process 3736 to run task
[2024-05-28T18:40:56.156+0000] {standard_task_runner.py:87} INFO - Running: ['***', 'tasks', 'run', 'fork2_dag', 'task1', 'scheduled__2024-05-28T18:40:40+00:00', '--job-id', '185', '--raw', '--subdir', 'DAGS_FOLDER/fork_2.py', '--cfg-path', '/tmp/tmppb3j1_ay']
[2024-05-28T18:40:56.163+0000] {standard_task_runner.py:88} INFO - Job 185: Subtask task1
[2024-05-28T18:40:56.205+0000] {warnings.py:109} WARNING - /home/***/.local/lib/python3.8/site-packages/***/settings.py:194: DeprecationWarning: The sql_alchemy_conn option in [core] has been moved to the sql_alchemy_conn option in [database] - the old setting has been used, but please update your config.
  SQL_ALCHEMY_CONN = conf.get("database", "SQL_ALCHEMY_CONN")

[2024-05-28T18:40:56.384+0000] {task_command.py:423} INFO - Running <TaskInstance: fork2_dag.task1 scheduled__2024-05-28T18:40:40+00:00 [running]> on host ac6c883b25f7
[2024-05-28T18:40:56.835+0000] {taskinstance.py:2480} INFO - Exporting env vars: AIRFLOW_CTX_DAG_OWNER='***' AIRFLOW_CTX_DAG_ID='fork2_dag' AIRFLOW_CTX_TASK_ID='task1' AIRFLOW_CTX_EXECUTION_DATE='2024-05-28T18:40:40+00:00' AIRFLOW_CTX_TRY_NUMBER='1' AIRFLOW_CTX_DAG_RUN_ID='scheduled__2024-05-28T18:40:40+00:00'
[2024-05-28T18:40:56.838+0000] {logging_mixin.py:188} INFO - 0.210691689421598
[2024-05-28T18:40:56.838+0000] {taskinstance.py:2698} ERROR - Task failed with exception
Traceback (most recent call last):
  File "/home/airflow/.local/lib/python3.8/site-packages/airflow/models/taskinstance.py", line 433, in _execute_task
    result = execute_callable(context=context, **execute_callable_kwargs)
  File "/home/airflow/.local/lib/python3.8/site-packages/airflow/operators/python.py", line 199, in execute
    return_value = self.execute_callable()
  File "/home/airflow/.local/lib/python3.8/site-packages/airflow/operators/python.py", line 216, in execute_callable
    return self.python_callable(*self.op_args, **self.op_kwargs)
  File "/opt/airflow/dags/fork_2.py", line 20, in random_fail_task
    raise Exception('This task randomly failed')
Exception: This task randomly failed
[2024-05-28T18:40:56.869+0000] {taskinstance.py:1138} INFO - Marking task as FAILED. dag_id=fork2_dag, task_id=task1, execution_date=20240528T184040, start_date=20240528T184055, end_date=20240528T184056
[2024-05-28T18:40:56.901+0000] {standard_task_runner.py:107} ERROR - Failed to execute job 185 for task task1 (This task randomly failed; 3736)
[2024-05-28T18:40:56.958+0000] {local_task_job_runner.py:234} INFO - Task exited with return code 1
[2024-05-28T18:40:57.043+0000] {taskinstance.py:3280} INFO - 1 downstream tasks scheduled from follow-on schedule check
