[2024-05-28T19:13:21.069+0000] {taskinstance.py:1956} INFO - Dependencies all met for dep_context=non-requeueable deps ti=<TaskInstance: fork3_dag.task2 scheduled__2024-05-28T19:12:20+00:00 [queued]>
[2024-05-28T19:13:21.161+0000] {taskinstance.py:1956} INFO - Dependencies all met for dep_context=requeueable deps ti=<TaskInstance: fork3_dag.task2 scheduled__2024-05-28T19:12:20+00:00 [queued]>
[2024-05-28T19:13:21.187+0000] {taskinstance.py:2170} INFO - Starting attempt 1 of 1
[2024-05-28T19:13:21.323+0000] {taskinstance.py:2191} INFO - Executing <Task(PythonOperator): task2> on 2024-05-28 19:12:20+00:00
[2024-05-28T19:13:21.391+0000] {standard_task_runner.py:60} INFO - Started process 5044 to run task
[2024-05-28T19:13:21.411+0000] {standard_task_runner.py:87} INFO - Running: ['***', 'tasks', 'run', 'fork3_dag', 'task2', 'scheduled__2024-05-28T19:12:20+00:00', '--job-id', '284', '--raw', '--subdir', 'DAGS_FOLDER/fork_3.py', '--cfg-path', '/tmp/tmpmyxj82_8']
[2024-05-28T19:13:21.451+0000] {standard_task_runner.py:88} INFO - Job 284: Subtask task2
[2024-05-28T19:13:21.580+0000] {warnings.py:109} WARNING - /home/***/.local/lib/python3.8/site-packages/***/settings.py:194: DeprecationWarning: The sql_alchemy_conn option in [core] has been moved to the sql_alchemy_conn option in [database] - the old setting has been used, but please update your config.
  SQL_ALCHEMY_CONN = conf.get("database", "SQL_ALCHEMY_CONN")

[2024-05-28T19:13:21.820+0000] {task_command.py:423} INFO - Running <TaskInstance: fork3_dag.task2 scheduled__2024-05-28T19:12:20+00:00 [running]> on host ac6c883b25f7
[2024-05-28T19:13:23.135+0000] {taskinstance.py:2480} INFO - Exporting env vars: AIRFLOW_CTX_DAG_OWNER='***' AIRFLOW_CTX_DAG_ID='fork3_dag' AIRFLOW_CTX_TASK_ID='task2' AIRFLOW_CTX_EXECUTION_DATE='2024-05-28T19:12:20+00:00' AIRFLOW_CTX_TRY_NUMBER='1' AIRFLOW_CTX_DAG_RUN_ID='scheduled__2024-05-28T19:12:20+00:00'
[2024-05-28T19:13:23.137+0000] {logging_mixin.py:188} INFO - 0.4227835951927361
[2024-05-28T19:13:23.138+0000] {taskinstance.py:2698} ERROR - Task failed with exception
Traceback (most recent call last):
  File "/home/airflow/.local/lib/python3.8/site-packages/airflow/models/taskinstance.py", line 433, in _execute_task
    result = execute_callable(context=context, **execute_callable_kwargs)
  File "/home/airflow/.local/lib/python3.8/site-packages/airflow/operators/python.py", line 199, in execute
    return_value = self.execute_callable()
  File "/home/airflow/.local/lib/python3.8/site-packages/airflow/operators/python.py", line 216, in execute_callable
    return self.python_callable(*self.op_args, **self.op_kwargs)
  File "/opt/airflow/dags/fork_3.py", line 20, in random_fail_task
    raise Exception('This task randomly failed')
Exception: This task randomly failed
[2024-05-28T19:13:23.226+0000] {taskinstance.py:1138} INFO - Marking task as FAILED. dag_id=fork3_dag, task_id=task2, execution_date=20240528T191220, start_date=20240528T191321, end_date=20240528T191323
[2024-05-28T19:13:23.402+0000] {standard_task_runner.py:107} ERROR - Failed to execute job 284 for task task2 (This task randomly failed; 5044)
[2024-05-28T19:13:23.569+0000] {local_task_job_runner.py:234} INFO - Task exited with return code 1
[2024-05-28T19:13:23.871+0000] {taskinstance.py:3280} INFO - 1 downstream tasks scheduled from follow-on schedule check
