[2024-05-28T18:41:46.534+0000] {taskinstance.py:1956} INFO - Dependencies all met for dep_context=non-requeueable deps ti=<TaskInstance: fork2_dag.task1 scheduled__2024-05-28T18:41:30+00:00 [queued]>
[2024-05-28T18:41:46.551+0000] {taskinstance.py:1956} INFO - Dependencies all met for dep_context=requeueable deps ti=<TaskInstance: fork2_dag.task1 scheduled__2024-05-28T18:41:30+00:00 [queued]>
[2024-05-28T18:41:46.551+0000] {taskinstance.py:2170} INFO - Starting attempt 1 of 1
[2024-05-28T18:41:46.584+0000] {taskinstance.py:2191} INFO - Executing <Task(PythonOperator): task1> on 2024-05-28 18:41:30+00:00
[2024-05-28T18:41:46.594+0000] {standard_task_runner.py:60} INFO - Started process 3801 to run task
[2024-05-28T18:41:46.602+0000] {standard_task_runner.py:87} INFO - Running: ['***', 'tasks', 'run', 'fork2_dag', 'task1', 'scheduled__2024-05-28T18:41:30+00:00', '--job-id', '201', '--raw', '--subdir', 'DAGS_FOLDER/fork_2.py', '--cfg-path', '/tmp/tmp5znmnhlt']
[2024-05-28T18:41:46.605+0000] {standard_task_runner.py:88} INFO - Job 201: Subtask task1
[2024-05-28T18:41:46.626+0000] {warnings.py:109} WARNING - /home/***/.local/lib/python3.8/site-packages/***/settings.py:194: DeprecationWarning: The sql_alchemy_conn option in [core] has been moved to the sql_alchemy_conn option in [database] - the old setting has been used, but please update your config.
  SQL_ALCHEMY_CONN = conf.get("database", "SQL_ALCHEMY_CONN")

[2024-05-28T18:41:46.696+0000] {task_command.py:423} INFO - Running <TaskInstance: fork2_dag.task1 scheduled__2024-05-28T18:41:30+00:00 [running]> on host ac6c883b25f7
[2024-05-28T18:41:46.856+0000] {taskinstance.py:2480} INFO - Exporting env vars: AIRFLOW_CTX_DAG_OWNER='***' AIRFLOW_CTX_DAG_ID='fork2_dag' AIRFLOW_CTX_TASK_ID='task1' AIRFLOW_CTX_EXECUTION_DATE='2024-05-28T18:41:30+00:00' AIRFLOW_CTX_TRY_NUMBER='1' AIRFLOW_CTX_DAG_RUN_ID='scheduled__2024-05-28T18:41:30+00:00'
[2024-05-28T18:41:46.858+0000] {logging_mixin.py:188} INFO - 0.6097646663145577
[2024-05-28T18:41:46.859+0000] {taskinstance.py:2698} ERROR - Task failed with exception
Traceback (most recent call last):
  File "/home/airflow/.local/lib/python3.8/site-packages/airflow/models/taskinstance.py", line 433, in _execute_task
    result = execute_callable(context=context, **execute_callable_kwargs)
  File "/home/airflow/.local/lib/python3.8/site-packages/airflow/operators/python.py", line 199, in execute
    return_value = self.execute_callable()
  File "/home/airflow/.local/lib/python3.8/site-packages/airflow/operators/python.py", line 216, in execute_callable
    return self.python_callable(*self.op_args, **self.op_kwargs)
  File "/opt/airflow/dags/fork_2.py", line 20, in random_fail_task
    raise Exception('This task randomly failed')
Exception: This task randomly failed
[2024-05-28T18:41:46.872+0000] {taskinstance.py:1138} INFO - Marking task as FAILED. dag_id=fork2_dag, task_id=task1, execution_date=20240528T184130, start_date=20240528T184146, end_date=20240528T184146
[2024-05-28T18:41:46.895+0000] {standard_task_runner.py:107} ERROR - Failed to execute job 201 for task task1 (This task randomly failed; 3801)
[2024-05-28T18:41:46.935+0000] {local_task_job_runner.py:234} INFO - Task exited with return code 1
[2024-05-28T18:41:46.984+0000] {taskinstance.py:3280} INFO - 1 downstream tasks scheduled from follow-on schedule check
